<?xml version="1.0"?>

<robot xmlns="http://drake.mit.edu"
 xmlns:xsi="http://www.w3.org/2001/XMLSchema-instance"
 name="box">

  <link name="box_x_link">
    <inertial>
      <origin xyz="0 0 0.2" rpy="0 0 0" />
      <mass value="0" />
      <inertia ixx="0.00" ixy="0" ixz="0" iyy="0.00" iyz="0" izz="0.00" />
    </inertial>
  </link>

  <link name="box">
    <inertial>
      <origin xyz="0 0 0.5" rpy="0 0 0" />
      <mass value="5.0" />
      <inertia ixx="0.166666666666667" ixy="0" ixz="0" iyy="0.166666666666667" iyz="0" izz="0.166666666666667" />
    </inertial>
    <visual>
      <origin xyz="0 0 0.5" rpy="0 0 0" />
      <geometry>
        <box size="0.999 0.999 0.999" />
      </geometry>
      <material>
        <color rgba="1 0 0 1" />
      </material>
    </visual>
    <collision name="collision">
        <origin xyz="0 0 0.5" rpy="0 0 0" />
        <geometry>
          <box size="0.999 0.999 0.999" />
        </geometry>
        <surface>
          <friction>
            <ode>
              <mu>2</mu>
              <mu2>0.5</mu2>
            </ode>
          </friction>
        </surface>
    </collision>
  </link>

  <joint name="box_x_slider" type="prismatic">
    <parent link="world" />
    <child link="box_x_link" />
    <origin xyz="0 0 0" />
    <axis xyz="1 0 0"/>
    <dynamics damping="100.0" /> 
  </joint>

  <joint name="box_y_slider" type="prismatic">
    <parent link="box_x_link" />
    <child link="box" />
    <origin xyz="0 0 0" />
    <axis xyz="0 1 0"/>
    <dynamics damping="100.0" />
  </joint>
  
</robot>
